File: Data/Specimen_RawData_2003.csv
Maximum Load;12,94;kN
Extension at Maximum Load;1,51;mm
Modulus (E-modulus);0,00;MPa
Modulus (Automatic Young's);54865,22;MPa
Tensile strain at Maximum Load;1,050;%
Tensile strain at Yield (Offset       0,2 %);0,00000;mm/mm
Tensile stress at Yield (Offset       0,2 %);0,00000;MPa
Tensile strain at Break (Standard);0,01050;mm/mm
Tensile stress at Break (Standard);500,00281;MPa

Time;Extension;Load;Strain 1;Tensile stress;Tensile strain
(sec);(mm);(N);(mm/mm);(MPa);(mm/mm)
0,00000;0,00;69,64;0,00001;2,69;0,00000
0,10000;0,00;70,08;0,00001;2,71;0,00000
0,20000;0,00;71,48;0,00000;2,76;0,00001
0,30000;0,01;99,08;0,00000;3,83;0,00004
0,40000;0,01;159,85;0,00001;6,18;0,00008
0,50000;0,02;194,40;0,00001;7,51;0,00011
0,60000;0,02;235,57;0,00001;9,10;0,00013
0,70000;0,02;268,22;0,00001;10,37;0,00016
0,80000;0,03;315,79;0,00001;12,20;0,00018
0,90000;0,03;349,92;0,00001;13,52;0,00021
1,00000;0,03;371,20;0,00001;14,35;0,00023
1,10000;0,04;407,67;0,00001;15,76;0,00025
1,20000;0,04;451,14;0,00001;17,44;0,00028
1,30000;0,04;477,08;0,00001;18,44;0,00030
1,40000;0,05;502,68;0,00001;19,43;0,00032
1,50000;0,05;538,71;0,00001;20,82;0,00035
1,60000;0,05;570,64;0,00001;22,05;0,00037
1,70000;0,06;608,80;0,00001;23,53;0,00039
1,80000;0,06;637,33;0,00001;24,63;0,00042
1,90000;0,06;667,81;0,00001;25,81;0,00044
2,00000;0,07;710,47;0,00001;27,46;0,00046
2,10000;0,07;753,79;0,00001;29,13;0,00049
2,20000;0,07;777,16;0,00001;30,03;0,00051
2,30000;0,08;792,66;0,00001;30,63;0,00053
2,40000;0,08;829,71;0,00000;32,07;0,00056
2,50000;0,08;874,78;0,00002;33,81;0,00058
2,60000;0,09;909,17;0,00001;35,14;0,00060
2,70000;0,09;938,38;0,00001;36,27;0,00062
2,80000;0,09;971,55;0,00001;37,55;0,00065
2,90000;0,10;1004,82;0,00001;38,83;0,00067
3,00000;0,10;1042,91;0,00001;40,31;0,00069
3,10000;0,10;1075,26;0,00001;41,56;0,00072
3,20000;0,11;1090,77;0,00001;42,16;0,00074
3,30000;0,11;1132,64;0,00001;43,77;0,00076
3,40000;0,11;1174,13;0,00001;45,38;0,00079
3,50000;0,12;1200,47;0,00001;46,40;0,00081
3,60000;0,12;1225,02;0,00001;47,34;0,00083
3,70000;0,12;1267,25;0,00001;48,98;0,00086
3,80000;0,13;1305,15;0,00001;50,44;0,00088
3,90000;0,13;1340,59;0,00001;51,81;0,00090
4,00000;0,13;1368,62;0,00001;52,89;0,00092
4,10000;0,14;1390,01;0,00001;53,72;0,00095
4,20000;0,14;1421,49;0,00001;54,94;0,00097
4,30000;0,14;1466,33;0,00001;56,67;0,00099
4,40000;0,15;1498,54;0,00001;57,91;0,00102
4,50000;0,15;1528,56;0,00001;59,07;0,00104
4,60000;0,15;1565,87;0,00001;60,52;0,00106
4,70000;0,16;1602,74;0,00001;61,94;0,00109
4,80000;0,16;1624,82;0,00001;62,80;0,00111
4,90000;0,16;1656,00;0,00001;64,00;0,00113
5,00000;0,17;1694,11;0,00001;65,47;0,00116
5,10000;0,17;1721,18;0,00001;66,52;0,00118
5,20000;0,17;1761,20;0,00001;68,07;0,00120
5,30000;0,18;1793,93;0,00001;69,33;0,00123
5,40000;0,18;1823,00;0,00001;70,45;0,00125
5,50000;0,18;1855,78;0,00001;71,72;0,00127
5,60000;0,19;1896,89;0,00001;73,31;0,00130
5,70000;0,19;1919,05;0,00001;74,17;0,00132
5,80000;0,19;1960,30;0,00001;75,76;0,00134
5,90000;0,20;1992,82;0,00001;77,02;0,00137
6,00000;0,20;2017,06;0,00001;77,95;0,00139
6,10000;0,20;2046,27;0,00001;79,08;0,00141
6,20000;0,21;2081,93;0,00001;80,46;0,00143
6,30000;0,21;2124,53;0,00001;82,11;0,00146
6,40000;0,21;2155,38;0,00001;83,30;0,00148
6,50000;0,22;2187,13;0,00001;84,53;0,00150
6,60000;0,22;2216,47;0,00001;85,66;0,00153
6,70000;0,22;2247,13;0,00000;86,85;0,00155
6,80000;0,23;2283,25;0,00001;88,24;0,00157
6,90000;0,23;2315,32;0,00001;89,48;0,00160
7,00000;0,23;2339,73;0,00001;90,42;0,00162
7,10000;0,24;2383,76;0,00002;92,13;0,00164
7,20000;0,24;2424,89;0,00001;93,72;0,00167
7,30000;0,24;2443,14;0,00001;94,42;0,00169
7,40000;0,25;2469,89;0,00001;95,45;0,00171
7,50000;0,25;2512,65;0,00001;97,11;0,00174
7,60000;0,25;2543,04;0,00001;98,28;0,00176
7,70000;0,26;2583,42;0,00001;99,84;0,00178
7,80000;0,26;2612,30;0,00001;100,96;0,00181
7,90000;0,26;2633,16;0,00001;101,76;0,00183
8,00000;0,27;2666,73;0,00001;103,06;0,00185
8,10000;0,27;2711,00;0,00001;104,77;0,00187
8,20000;0,27;2741,58;0,00001;105,95;0,00190
8,30000;0,28;2763,61;0,00001;106,81;0,00192
8,40000;0,28;2802,39;0,00001;108,30;0,00194
8,50000;0,28;2841,06;0,00001;109,80;0,00197
8,60000;0,29;2868,47;0,00001;110,86;0,00199
8,70000;0,29;2893,30;0,00001;111,82;0,00201
8,80000;0,29;2931,17;0,00001;113,28;0,00204
8,90000;0,30;2961,10;0,00000;114,44;0,00206
9,00000;0,30;3002,03;0,00001;116,02;0,00208
9,10000;0,30;3036,76;0,00001;117,36;0,00211
9,20000;0,31;3049,95;0,00001;117,87;0,00213
9,30000;0,31;3082,77;0,00001;119,14;0,00215
9,40000;0,31;3130,59;0,00001;120,99;0,00218
9,50000;0,32;3161,80;0,00000;122,20;0,00220
9,60000;0,32;3189,69;0,00001;123,27;0,00222
9,70000;0,32;3222,74;0,00001;124,55;0,00225
9,80000;0,33;3254,96;0,00001;125,80;0,00227
9,90000;0,33;3283,63;0,00000;126,90;0,00229
10,00000;0,33;3319,81;0,00000;128,30;0,00231
10,10000;0,34;3352,78;0,00001;129,58;0,00234
10,20000;0,34;3375,72;0,00000;130,46;0,00236
10,30000;0,34;3421,48;0,00000;132,23;0,00238
10,40000;0,35;3455,53;0,00001;133,55;0,00241
10,50000;0,35;3474,55;0,00000;134,28;0,00243
10,60000;0,35;3505,95;0,00001;135,50;0,00245
10,70000;0,36;3547,92;0,00000;137,12;0,00248
10,80000;0,36;3572,69;0,00000;138,07;0,00250
10,90000;0,36;3608,58;0,00000;139,46;0,00252
11,00000;0,37;3644,05;0,00000;140,83;0,00255
11,10000;0,37;3667,70;0,00000;141,75;0,00257
11,20000;0,37;3697,98;0,00000;142,92;0,00259
11,30000;0,38;3740,25;0,00000;144,55;0,00262
11,40000;0,38;3773,78;0,00000;145,85;0,00264
11,50000;0,38;3799,29;0,00000;146,83;0,00266
11,60000;0,39;3836,97;0,00000;148,29;0,00269
11,70000;0,39;3866,19;0,00000;149,42;0,00271
11,80000;0,39;3886,32;0,00000;150,20;0,00273
11,90000;0,40;3923,91;0,00000;151,65;0,00275
12,00000;0,40;3964,88;0,00000;153,23;0,00278
12,10000;0,40;3987,00;0,00000;154,09;0,00280
12,20000;0,41;4025,74;0,00000;155,58;0,00282
12,30000;0,41;4066,40;0,00000;157,16;0,00285
12,40000;0,41;4090,62;0,00000;158,09;0,00287
12,50000;0,42;4116,55;0,00000;159,09;0,00289
12,60000;0,42;4151,63;0,00000;160,45;0,00292
12,70000;0,42;4179,82;0,00000;161,54;0,00294
12,80000;0,43;4209,56;0,00000;162,69;0,00296
12,90000;0,43;4255,21;0,00000;164,45;0,00299
13,00000;0,43;4282,30;0,00000;165,50;0,00301
13,10000;0,44;4304,31;0,00000;166,35;0,00303
13,20000;0,44;4343,86;0,00000;167,88;0,00306
13,30000;0,44;4384,81;0,00000;169,46;0,00308
13,40000;0,45;4404,75;0,00000;170,23;0,00310
13,50000;0,45;4436,11;-0,00001;171,44;0,00313
13,60000;0,45;4469,41;0,00000;172,73;0,00315
13,70000;0,46;4495,27;0,00000;173,73;0,00317
13,80000;0,46;4531,99;0,00000;175,15;0,00320
13,90000;0,46;4568,75;0,00000;176,57;0,00322
14,00000;0,47;4593,87;0,00000;177,54;0,00324
14,10000;0,47;4625,48;0,00000;178,76;0,00326
14,20000;0,47;4672,56;0,00000;180,58;0,00329
14,30000;0,48;4699,46;0,00000;181,62;0,00331
14,40000;0,48;4715,71;0,00000;182,25;0,00333
14,50000;0,48;4748,95;0,00000;183,53;0,00336
14,60000;0,49;4784,10;0,00000;184,89;0,00338
14,70000;0,49;4815,18;0,00000;186,09;0,00340
14,80000;0,49;4854,40;0,00000;187,61;0,00343
14,90000;0,50;4883,71;0,00000;188,74;0,00345
15,00000;0,50;4907,63;0,00000;189,67;0,00347
15,10000;0,50;4946,89;0,00000;191,18;0,00350
15,20000;0,51;4984,38;0,00000;192,63;0,00352
15,30000;0,51;5008,43;0,00000;193,56;0,00354
15,40000;0,51;5033,08;0,00000;194,52;0,00357
15,50000;0,52;5070,73;0,00000;195,97;0,00359
15,60000;0,52;5102,14;0,00000;197,18;0,00361
15,70000;0,52;5131,46;0,00000;198,32;0,00364
15,80000;0,53;5163,35;0,00000;199,55;0,00366
15,90000;0,53;5195,12;0,00000;200,78;0,00368
16,00000;0,53;5229,16;0,00000;202,09;0,00370
16,10000;0,54;5266,69;0,00000;203,54;0,00373
16,20000;0,54;5295,16;-0,00001;204,64;0,00375
16,30000;0,54;5316,80;0,00000;205,48;0,00377
16,40000;0,55;5345,50;0,00000;206,59;0,00380
16,50000;0,55;5382,35;-0,00001;208,01;0,00382
16,60000;0,55;5418,37;0,00000;209,41;0,00384
16,70000;0,56;5449,52;0,00000;210,61;0,00387
16,80000;0,56;5481,17;0,00000;211,83;0,00389
16,90000;0,56;5511,97;-0,00001;213,02;0,00391
17,00000;0,57;5542,13;0,00000;214,19;0,00394
17,10000;0,57;5571,66;0,00000;215,33;0,00396
17,20000;0,57;5603,99;-0,00001;216,58;0,00398
17,30000;0,58;5630,66;0,00000;217,61;0,00401
17,40000;0,58;5661,10;0,00000;218,79;0,00403
17,50000;0,58;5697,07;0,00000;220,18;0,00405
17,60000;0,59;5729,48;0,00000;221,43;0,00407
17,70000;0,59;5753,34;-0,00001;222,35;0,00410
17,80000;0,59;5787,27;-0,00001;223,66;0,00412
17,90000;0,60;5822,54;0,00000;225,03;0,00414
18,00000;0,60;5851,01;0,00000;226,13;0,00417
18,10000;0,60;5881,71;0,00000;227,31;0,00419
18,20000;0,61;5915,97;0,00000;228,64;0,00421
18,30000;0,61;5941,07;0,00000;229,61;0,00424
18,40000;0,61;5963,23;0,00000;230,46;0,00426
18,50000;0,62;6002,85;0,00000;231,99;0,00428
18,60000;0,62;6035,01;0,00000;233,24;0,00431
18,70000;0,62;6063,99;0,00000;234,36;0,00433
18,80000;0,63;6097,42;0,00000;235,65;0,00435
18,90000;0,63;6128,72;0,00000;236,86;0,00438
19,00000;0,63;6153,60;0,00000;237,82;0,00440
19,10000;0,64;6179,42;0,00000;238,82;0,00442
19,20000;0,64;6219,65;0,00000;240,37;0,00445
19,30000;0,64;6245,03;0,00000;241,35;0,00447
19,40000;0,65;6271,52;0,00000;242,38;0,00449
19,50000;0,65;6309,39;0,00000;243,84;0,00451
19,60000;0,65;6341,44;0,00000;245,08;0,00454
19,70000;0,66;6366,65;0,00000;246,05;0,00456
19,80000;0,66;6394,28;0,00000;247,12;0,00458
19,90000;0,66;6425,74;0,00000;248,34;0,00461
20,00000;0,67;6452,73;0,00000;249,38;0,00463
20,10000;0,67;6489,56;0,00000;250,80;0,00465
20,20000;0,67;6524,12;0,00000;252,14;0,00468
20,30000;0,68;6546,99;0,00000;253,02;0,00470
20,40000;0,68;6571,81;0,00000;253,98;0,00472
20,50000;0,68;6601,33;0,00000;255,12;0,00475
20,60000;0,69;6638,20;0,00000;256,55;0,00477
20,70000;0,69;6667,16;0,00000;257,67;0,00479
20,80000;0,69;6695,02;0,00000;258,74;0,00482
20,90000;0,70;6725,10;0,00000;259,91;0,00484
21,00000;0,70;6755,49;0,00000;261,08;0,00486
21,10000;0,70;6784,40;0,00000;262,20;0,00488
21,20000;0,71;6809,02;0,00000;263,15;0,00491
21,30000;0,71;6841,17;0,00000;264,39;0,00493
21,40000;0,71;6868,69;0,00000;265,46;0,00495
21,50000;0,72;6898,41;0,00000;266,61;0,00498
21,60000;0,72;6936,27;0,00000;268,07;0,00500
21,70000;0,72;6963,63;0,00000;269,13;0,00502
21,80000;0,73;6988,02;0,00000;270,07;0,00505
21,90000;0,73;7013,90;0,00000;271,07;0,00507
22,00000;0,73;7048,64;0,00000;272,41;0,00509
22,10000;0,74;7078,03;0,00000;273,55;0,00512
22,20000;0,74;7104,85;0,00000;274,58;0,00514
22,30000;0,74;7141,31;0,00000;275,99;0,00516
22,40000;0,75;7162,52;0,00000;276,81;0,00519
22,50000;0,75;7187,72;-0,00001;277,79;0,00521
22,60000;0,75;7219,85;0,00000;279,03;0,00523
22,70000;0,76;7250,05;0,00000;280,20;0,00525
22,80000;0,76;7276,32;-0,00001;281,21;0,00528
22,90000;0,76;7305,69;0,00000;282,35;0,00530
23,00000;0,77;7341,14;0,00000;283,72;0,00532
23,10000;0,77;7367,24;0,00000;284,72;0,00535
23,20000;0,77;7394,90;0,00000;285,79;0,00537
23,30000;0,78;7421,80;0,00000;286,83;0,00539
23,40000;0,78;7451,07;0,00000;287,96;0,00542
23,50000;0,78;7480,09;0,00000;289,09;0,00544
23,60000;0,79;7509,47;0,00000;290,22;0,00546
23,70000;0,79;7538,42;0,00000;291,34;0,00549
23,80000;0,79;7566,46;-0,00001;292,42;0,00551
23,90000;0,80;7593,40;0,00000;293,46;0,00553
24,00000;0,80;7618,67;-0,00001;294,44;0,00556
24,10000;0,80;7646,63;-0,00001;295,52;0,00558
24,20000;0,81;7680,14;0,00000;296,82;0,00560
24,30000;0,81;7709,21;0,00000;297,94;0,00562
24,40000;0,81;7731,94;-0,00001;298,82;0,00565
24,50000;0,82;7766,40;0,00000;300,15;0,00567
24,60000;0,82;7785,84;-0,00001;300,90;0,00569
24,70000;0,82;7810,75;-0,00001;301,86;0,00572
24,80000;0,83;7840,93;0,00000;303,03;0,00574
24,90000;0,83;7868,07;0,00000;304,08;0,00576
25,00000;0,83;7894,94;0,00000;305,12;0,00579
25,10000;0,84;7922,77;0,00000;306,19;0,00581
25,20000;0,84;7954,80;0,00000;307,43;0,00583
25,30000;0,84;7983,98;0,00000;308,56;0,00586
25,40000;0,85;8006,62;-0,00001;309,43;0,00588
25,50000;0,85;8029,90;0,00000;310,33;0,00590
25,60000;0,85;8056,84;0,00000;311,38;0,00592
25,70000;0,86;8080,10;-0,00001;312,27;0,00595
25,80000;0,86;8112,86;-0,00001;313,54;0,00597
25,90000;0,86;8138,08;-0,00001;314,52;0,00600
26,00000;0,87;8170,73;-0,00001;315,78;0,00602
26,10000;0,87;8196,75;0,00000;316,78;0,00604
26,20000;0,87;8216,40;-0,00001;317,54;0,00606
26,30000;0,88;8241,99;-0,00001;318,53;0,00609
26,40000;0,88;8275,48;-0,00001;319,83;0,00611
26,50000;0,88;8301,04;-0,00001;320,81;0,00613
26,60000;0,89;8328,36;0,00000;321,87;0,00616
26,70000;0,89;8352,90;-0,00001;322,82;0,00618
26,80000;0,89;8380,78;-0,00001;323,90;0,00620
26,90000;0,90;8399,14;-0,00001;324,60;0,00623
27,00000;0,90;8427,85;0,00000;325,71;0,00625
27,10000;0,90;8454,23;0,00000;326,73;0,00627
27,20000;0,91;8479,76;-0,00001;327,72;0,00630
27,30000;0,91;8512,48;-0,00001;328,98;0,00632
27,40000;0,91;8543,07;-0,00001;330,17;0,00634
27,50000;0,92;8566,41;0,00000;331,07;0,00637
27,60000;0,92;8597,95;0,00000;332,29;0,00639
27,70000;0,92;8621,29;-0,00001;333,19;0,00641
27,80000;0,93;8642,27;-0,00001;334,00;0,00643
27,90000;0,93;8671,31;0,00000;335,12;0,00646
28,00000;0,93;8695,17;0,00000;336,05;0,00648
28,10000;0,94;8721,72;0,00000;337,07;0,00650
28,20000;0,94;8752,59;-0,00001;338,26;0,00653
28,30000;0,94;8776,65;0,00000;339,19;0,00655
28,40000;0,95;8802,88;-0,00001;340,21;0,00657
28,50000;0,95;8832,96;-0,00001;341,37;0,00660
28,60000;0,95;8856,28;0,00000;342,27;0,00662
28,70000;0,96;8881,17;0,00000;343,23;0,00664
28,80000;0,96;8905,54;0,00000;344,18;0,00667
28,90000;0,96;8935,59;0,00000;345,34;0,00669
29,00000;0,97;8958,42;0,00000;346,22;0,00671
29,10000;0,97;8980,39;-0,00001;347,07;0,00674
29,20000;0,97;9008,88;0,00000;348,17;0,00676
29,30000;0,98;9031,69;0,00000;349,05;0,00678
29,40000;0,98;9053,49;-0,00001;349,89;0,00681
29,50000;0,98;9085,42;0,00000;351,13;0,00683
29,60000;0,99;9111,43;0,00000;352,13;0,00685
29,70000;0,99;9136,50;-0,00001;353,10;0,00687
29,80000;0,99;9165,10;0,00000;354,21;0,00690
29,90000;1,00;9190,93;-0,00001;355,20;0,00692
30,00000;1,00;9215,48;-0,00001;356,15;0,00694
30,10000;1,00;9242,19;0,00000;357,19;0,00697
30,20000;1,01;9264,80;-0,00001;358,06;0,00699
30,30000;1,01;9287,63;-0,00001;358,94;0,00701
30,40000;1,01;9311,07;-0,00001;359,85;0,00704
30,50000;1,02;9342,92;0,00000;361,08;0,00706
30,60000;1,02;9368,68;0,00000;362,07;0,00708
30,70000;1,02;9394,64;-0,00001;363,08;0,00711
30,80000;1,03;9423,08;0,00000;364,18;0,00713
30,90000;1,03;9443,70;0,00000;364,97;0,00715
31,00000;1,03;9466,21;0,00000;365,84;0,00718
31,10000;1,04;9494,05;0,00000;366,92;0,00720
31,20000;1,04;9518,84;-0,00001;367,88;0,00722
31,30000;1,04;9539,74;0,00000;368,69;0,00724
31,40000;1,05;9570,58;0,00000;369,88;0,00727
31,50000;1,05;9590,42;-0,00001;370,64;0,00729
31,60000;1,05;9615,15;0,00000;371,60;0,00731
31,70000;1,06;9643,03;-0,00001;372,68;0,00734
31,80000;1,06;9669,81;-0,00001;373,71;0,00736
31,90000;1,06;9687,89;-0,00001;374,41;0,00738
32,00000;1,07;9714,38;0,00000;375,44;0,00741
32,10000;1,07;9738,86;0,00000;376,38;0,00743
32,20000;1,07;9766,42;-0,00001;377,45;0,00745
32,30000;1,08;9792,42;-0,00001;378,45;0,00748
32,40000;1,08;9821,80;-0,00001;379,59;0,00750
32,50000;1,08;9841,27;0,00000;380,34;0,00752
32,60000;1,09;9865,85;-0,00001;381,29;0,00755
32,70000;1,09;9886,02;-0,00001;382,07;0,00757
32,80000;1,09;9908,84;0,00000;382,95;0,00759
32,90000;1,10;9939,25;0,00000;384,13;0,00762
33,00000;1,10;9970,84;-0,00001;385,35;0,00764
33,10000;1,10;9991,83;-0,00001;386,16;0,00766
33,20000;1,11;10015,60;-0,00001;387,08;0,00769
33,30000;1,11;10041,31;-0,00001;388,07;0,00771
33,40000;1,11;10063,27;0,00000;388,92;0,00773
33,50000;1,12;10087,23;-0,00001;389,84;0,00775
33,60000;1,12;10113,59;0,00000;390,86;0,00778
33,70000;1,12;10133,85;0,00000;391,65;0,00780
33,80000;1,13;10154,79;-0,00001;392,46;0,00782
33,90000;1,13;10185,64;0,00000;393,65;0,00785
34,00000;1,13;10209,66;0,00000;394,58;0,00787
34,10000;1,14;10232,76;0,00000;395,47;0,00789
34,20000;1,14;10256,74;0,00000;396,40;0,00792
34,30000;1,14;10276,85;0,00000;397,17;0,00794
34,40000;1,15;10294,99;0,00000;397,87;0,00796
34,50000;1,15;10324,33;0,00000;399,01;0,00799
34,60000;1,15;10348,87;0,00000;399,96;0,00801
34,70000;1,16;10373,98;0,00000;400,93;0,00803
34,80000;1,16;10402,09;0,00000;402,01;0,00806
34,90000;1,16;10423,99;0,00000;402,86;0,00808
35,00000;1,17;10442,79;0,00000;403,59;0,00810
35,10000;1,17;10465,00;0,00000;404,44;0,00813
35,20000;1,17;10495,95;-0,00001;405,64;0,00815
35,30000;1,18;10517,02;0,00000;406,46;0,00817
35,40000;1,18;10541,18;0,00000;407,39;0,00819
35,50000;1,18;10565,47;0,00000;408,33;0,00822
35,60000;1,19;10593,05;-0,00001;409,39;0,00824
35,70000;1,19;10615,55;0,00000;410,26;0,00826
35,80000;1,19;10648,82;-0,00001;411,55;0,00829
35,90000;1,20;10666,80;0,00000;412,24;0,00831
36,00000;1,20;10690,39;0,00000;413,16;0,00833
36,10000;1,20;10714,18;0,00000;414,07;0,00836
36,20000;1,21;10735,98;0,00000;414,92;0,00838
36,30000;1,21;10757,48;0,00000;415,75;0,00840
36,40000;1,21;10793,60;0,00000;417,14;0,00843
36,50000;1,22;10818,60;0,00000;418,11;0,00845
36,60000;1,22;10835,31;0,00000;418,76;0,00847
36,70000;1,22;10860,21;0,00000;419,72;0,00850
36,80000;1,23;10882,56;0,00000;420,58;0,00852
36,90000;1,23;10906,28;0,00000;421,50;0,00854
37,00000;1,23;10934,09;0,00000;422,57;0,00857
37,10000;1,24;10956,16;0,00000;423,43;0,00859
37,20000;1,24;10974,39;0,00000;424,13;0,00861
37,30000;1,24;11006,48;0,00000;425,37;0,00864
37,40000;1,25;11029,05;0,00000;426,24;0,00866
37,50000;1,25;11051,01;0,00000;427,09;0,00868
37,60000;1,25;11078,91;0,00000;428,17;0,00870
37,70000;1,26;11106,60;0,00000;429,24;0,00873
37,80000;1,26;11124,21;0,00000;429,92;0,00875
37,90000;1,26;11148,00;0,00000;430,84;0,00877
38,00000;1,27;11172,01;0,00000;431,77;0,00880
38,10000;1,27;11198,63;0,00000;432,80;0,00882
38,20000;1,27;11227,72;0,00000;433,92;0,00884
38,30000;1,28;11254,10;0,00000;434,94;0,00887
38,40000;1,28;11272,42;0,00000;435,65;0,00889
38,50000;1,28;11292,22;0,00000;436,41;0,00891
38,60000;1,29;11324,87;0,00000;437,68;0,00894
38,70000;1,29;11351,20;0,00000;438,69;0,00896
38,80000;1,29;11369,17;0,00000;439,39;0,00898
38,90000;1,30;11395,25;0,00000;440,40;0,00901
39,00000;1,30;11423,15;0,00000;441,47;0,00903
39,10000;1,30;11442,26;0,00000;442,21;0,00905
39,20000;1,31;11468,70;0,00000;443,23;0,00907
39,30000;1,31;11491,75;0,00001;444,13;0,00910
39,40000;1,31;11518,45;0,00000;445,16;0,00912
39,50000;1,32;11544,41;0,00000;446,16;0,00914
39,60000;1,32;11565,70;0,00001;446,98;0,00917
39,70000;1,32;11583,80;0,00000;447,68;0,00919
39,80000;1,33;11618,62;0,00000;449,03;0,00921
39,90000;1,33;11648,30;0,00000;450,18;0,00924
40,00000;1,33;11665,64;0,00000;450,85;0,00926
40,10000;1,34;11686,73;0,00001;451,66;0,00928
40,20000;1,34;11711,57;0,00000;452,62;0,00931
40,30000;1,34;11733,85;0,00000;453,48;0,00933
40,40000;1,35;11761,61;0,00001;454,55;0,00935
40,50000;1,35;11784,60;0,00001;455,44;0,00938
40,60000;1,35;11805,15;0,00001;456,24;0,00940
40,70000;1,36;11834,82;0,00001;457,38;0,00942
40,80000;1,36;11860,19;0,00000;458,36;0,00945
40,90000;1,36;11882,87;0,00001;459,24;0,00947
41,00000;1,37;11907,78;0,00001;460,20;0,00949
41,10000;1,37;11937,12;0,00001;461,34;0,00951
41,20000;1,37;11957,82;0,00001;462,14;0,00954
41,30000;1,38;11976,19;0,00000;462,85;0,00956
41,40000;1,38;11999,13;0,00001;463,73;0,00958
41,50000;1,38;12030,06;0,00001;464,93;0,00961
41,60000;1,39;12056,53;0,00001;465,95;0,00963
41,70000;1,39;12077,85;0,00001;466,78;0,00965
41,80000;1,39;12098,23;0,00001;467,56;0,00968
41,90000;1,40;12119,52;0,00001;468,39;0,00970
42,00000;1,40;12152,04;0,00001;469,64;0,00972
42,10000;1,40;12176,58;0,00001;470,59;0,00975
42,20000;1,41;12197,12;0,00001;471,39;0,00977
42,30000;1,41;12223,32;0,00001;472,40;0,00979
42,40000;1,41;12251,20;0,00001;473,48;0,00982
42,50000;1,42;12267,72;0,00001;474,11;0,00984
42,60000;1,42;12292,09;0,00001;475,06;0,00986
42,70000;1,42;12320,18;0,00001;476,14;0,00988
42,80000;1,43;12345,45;0,00001;477,12;0,00991
42,90000;1,43;12368,43;0,00001;478,01;0,00993
43,00000;1,43;12386,03;0,00001;478,69;0,00995
43,10000;1,44;12398,84;0,00001;479,18;0,00998
43,20000;1,44;12425,86;0,00001;480,23;0,01000
43,30000;1,44;12465,05;0,00000;481,74;0,01002
43,40000;1,45;12488,70;0,00001;482,66;0,01005
43,50000;1,45;12502,10;0,00001;483,17;0,01007
43,60000;1,45;12524,66;0,00001;484,04;0,01009
43,70000;1,46;12549,82;0,00001;485,02;0,01012
43,80000;1,46;12574,04;0,00001;485,95;0,01014
43,90000;1,46;12597,77;0,00001;486,87;0,01016
44,00000;1,47;12620,68;0,00001;487,76;0,01019
44,10000;1,47;12647,11;0,00001;488,78;0,01021
44,20000;1,47;12672,95;0,00001;489,78;0,01023
44,30000;1,48;12687,05;0,00001;490,32;0,01025
44,40000;1,48;12705,03;0,00001;491,02;0,01028
44,50000;1,48;12737,00;0,00001;492,25;0,01030
44,60000;1,49;12771,43;0,00001;493,58;0,01032
44,70000;1,49;12792,34;0,00001;494,39;0,01035
44,80000;1,49;12807,94;0,00001;494,99;0,01037
44,90000;1,50;12827,64;0,00001;495,75;0,01039
45,00000;1,50;12856,42;0,00001;496,87;0,01042
45,10000;1,50;12883,23;0,00001;497,90;0,01044
45,20000;1,51;12908,76;0,00001;498,89;0,01046
45,30000;1,51;12928,48;0,00001;499,65;0,01049
45,34600;1,51;12937,57;0,00001;500,00;0,01050